<?xml version="1.0"?>

<robot name="akira_hardware" xmlns:xacro="http://ros.org/wiki/xacro">

  <!-- Macro for EddieBot body. Including Gazebo extensions, but does not include Kinect -->
  <!-- <include filename="$(find akira_description)/urdf/gazebo.urdf.xacro"/> -->

  <material name="Green">
    <color rgba="0.0 0.8 0.0 1.0"/>
  </material>

  <material name="blue">
    <color rgba="0 0 1 1"/>
  </material>

  <material name="white">
    <color rgba="1.0 1.0 1.0 1.0"/>
  </material>

  <xacro:macro name="akira_body">

  <!-- base_footprint is a fictitious link(frame) that is on the ground right below base_link origin, navigation stack depends on this frame -->

  <link name="base_footprint">

<!--
    <inertial>
      <mass value="0.0001" />
      <origin xyz="0 0 0" />
      <inertia ixx="0.0001" ixy="0.0" ixz="0.0"
              iyy="0.0001" iyz="0.0" 
              izz="0.0001" />
    </inertial>
-->

    <visual>
      <origin xyz="0 0 0" rpy="0 0 0" />
      <geometry>
      <!--  <cylinder length="0.01" radius="0.225"/> -->
      <box size="0.001 0.001 0.001" />
      </geometry>
      <material name="Green" />
    </visual>

    <collision>
      <origin xyz="0 0 0" rpy="0 0 0" />
      <geometry>
      <!--  <cylinder length="0.01" radius="0.225"/> -->
      <box size="0.001 0.001 0.001" /> 
      </geometry>
    </collision>

  </link>

  <link name="base_link">

    <inertial>
      <mass value="2" />
      <origin xyz="0 0 0" />
      <inertia ixx="0.01" ixy="0.0" ixz="0.0"
        iyy="0.01" iyz="0.0" izz="0.5" />
    </inertial>

    <visual>
      <origin xyz=" 0 0 0" rpy="0 0 0" />
      <geometry>
        <!-- <mesh filename="package://eddiebot_description/meshes/create_body.dae"/> -->
        <cylinder length="0.01" radius="0.225"/>
      </geometry>
      <material name="Black" />
    </visual>

    <collision>
      <origin xyz="0.0 0.0 0.0" rpy="0 0 0" />
      <geometry>
        <cylinder length="0.01" radius="0.225"/>
      </geometry>
    </collision>
  </link>

  <joint name="base_footprint_joint" type="fixed">
    <origin xyz="0 0 0.11" rpy="0 0 0" />        
    <parent link="base_footprint"/>
    <child link="base_link" />
  </joint>

  <link name="left_wheel_link">

    <inertial>
      <origin xyz="0 0 0"/>
      <mass value="0.01" />
      <inertia ixx="0.001" ixy="0.0" ixz="0.0"
        iyy="0.001" iyz="0.0" izz="0.001" />
    </inertial>

    <visual>
      <origin xyz="0 0 0" rpy="0 1.5707 1.5707" />
      <geometry>
        <cylinder radius="0.072" length = "0.03"/>
      </geometry>
    </visual>

    <collision>
      <origin xyz="0 0 0" rpy="0 1.5707 1.5707" />
      <geometry>
        <cylinder radius="0.072" length = "0.03"/>
      </geometry>
    </collision>

  </link>

  <joint name="left_wheel_joint" type="continuous">
    <origin xyz="0 0.205 -0.038" rpy="0 0 0"/>
    <parent link="base_link"/>
    <child link="left_wheel_link"/>
    <axis xyz="0 1 0"/>
  </joint>

  <link name="right_wheel_link">

    <inertial>
      <origin xyz="0 0 0"/>
      <mass value="0.01" />
      <inertia ixx="0.001" ixy="0.0" ixz="0.0"
        iyy="0.001" iyz="0.0" izz="0.001" />
    </inertial>

    <visual>
      <origin xyz="0 0 0" rpy="0 1.5707 1.5707" />
      <geometry>
        <cylinder radius="0.072" length = "0.03"/>
      </geometry>
    </visual>

    <collision>
      <origin xyz="0 0 0" rpy="0 1.5707 1.5707" />
      <geometry>
        <cylinder radius="0.072" length = "0.03"/>
      </geometry>
    </collision>

  </link>

  <joint name="right_wheel_joint" type="continuous">
    <origin xyz="0 -0.205 -0.038" rpy="0 0 0"/>
    <parent link="base_link"/>
    <child link="right_wheel_link"/>
    <axis xyz="0 1 0"/>
  </joint>

  <link name="rear_wheel_link">

    <inertial>
      <origin xyz="0 0 0"/>
      <mass value="0.001" />
      <inertia ixx="0.0001" ixy="0.0" ixz="0.0"
        iyy="0.0001" iyz="0.0" izz="0.0001" />
    </inertial>

    <visual>
      <origin xyz="0 0 0" rpy="0 1.5707 1.5707"/>
      <geometry>
        <sphere radius="0.035" />
      </geometry>
    </visual>

    <collision>
      <origin xyz="0 0 0" rpy="0 1.5707 1.5707" />
      <geometry>
        <sphere radius="0.035" />
      </geometry>
    </collision>

  </link>

  <!-- fixed because there's no transmission -->
  <joint name="rear_castor_joint" type="fixed">
    <origin xyz="-0.1425 0 -0.075" rpy="0 0 0"/>
    <parent link="base_link"/>
    <child link="rear_wheel_link"/>
    <axis xyz="0 1 0"/>
  </joint>

  <link name="front_wheel_link">

    <inertial>
      <origin xyz="0 0 0" />
      <mass value="0.01" />
      <inertia ixx="0.001" ixy="0.0" ixz="0.0"
        iyy="0.001" iyz="0.0" izz="0.001" />
    </inertial>

    <visual>
      <origin xyz="0 0 0" rpy="0 1.5707 1.5707"/>
      <geometry>
        <sphere radius="0.035" />
      </geometry>
    </visual>

    <collision>
      <origin xyz="0 0 0" rpy="0 1.5707 1.5707" />
      <geometry>
        <sphere radius="0.035" />
      </geometry>
    </collision>

  </link>

  <!-- fixed because there's no transmission -->
  <joint name="front_castor_joint" type="fixed">
    <origin xyz="0.1425 0 -0.075" rpy="0 0 0"/>
    <parent link="base_link"/>
    <child link="front_wheel_link"/>
    <axis xyz="0 1 0"/>
  </joint>

  <joint name="plate_0_joint" type="fixed">
    <origin xyz="0 0 0.180" rpy="0 0 0" />
    <parent link="base_link"/>
    <child link="plate_0_link" />
  </joint>

  <link name="plate_0_link">

    <inertial>
      <mass value="0.01" />
      <origin xyz="0 0 0" />
      <inertia ixx="0.01" ixy="0.0" ixz="0.0"
        iyy="0.01" iyz="0.0"
        izz="0.01" />
    </inertial>

    <visual>
      <origin xyz=" 0 0 0 " rpy="0 0 0" />
      <geometry>
        <cylinder radius="0.225" length = "0.01"/>
      <!-- <mesh filename="package://eddiebot_description/meshes/plate_0_logo.dae"/> -->
      </geometry>
      <material name="Black" />
    </visual>

    <collision>
      <origin xyz="0.0 0.0 0.0" rpy="0 0 0" />
      <geometry>
        <cylinder radius="0.225" length = "0.01"/>
      <!-- <box size="0.233502 0.314845 0.006401"/> -->
      </geometry>
    </collision>

  </link>

  <joint name="laser_joint" type="fixed">
    <origin xyz="0.162 0.01 0.037" rpy="0 0 0" />
    <parent link="plate_0_link" />
    <child link="base_laser" />
  </joint>

  <link name="base_laser">

    <visual>
      <geometry>
        <box size="0.104 0.106 0.064" />
      </geometry>
      <material name="Green" />
    </visual>

    <inertial>
      <mass value="0.001" />
      <origin xyz="0 0 0" />
      <inertia ixx="0.0001" ixy="0.0" ixz="0.0"
        iyy="0.0001" iyz="0.0"
        izz="0.0001" />
    </inertial>

  </link>

  <joint name="plate_1_joint" type="fixed">
    <origin xyz="0 0 0.277" rpy="0 0 0" />
    <parent link="plate_0_link"/>
    <child link="plate_1_link" />
  </joint>

  <link name="plate_1_link">

    <inertial>
      <mass value="0.1" />
      <origin xyz="0 0 0" />
      <inertia ixx="0.01" ixy="0.0" ixz="0.0"
        iyy="0.01" iyz="0.0"
        izz="0.01" />
    </inertial>

    <visual>
      <origin xyz=" 0 0 0 " rpy="0 0 0" />
      <geometry>
        <cylinder radius="0.225" length = "0.01"/>
      <!-- <mesh filename="package://eddiebot_description/meshes/plate_1_logo.dae"/> -->
      </geometry>
      <material name="Black" />
    </visual>

    <collision>
      <origin xyz=" 0.0 0.0 0.0 " rpy="0 0 0" />
      <geometry>
        <cylinder radius="0.225" length = "0.01"/>
      <!-- <box size="0.314856 0.314856 0.006401"/> -->
      </geometry>
    </collision>

  </link>

  <joint name="base_camera_joint" type="fixed">
    <origin xyz="0.135 0 0.045" rpy="0 0 0" />
    <parent link="plate_1_link" />
    <child link="camera_link" />
  </joint>

  <link name="camera_link">

    <inertial>
      <mass value="0.01" />
      <origin xyz="0 0 0" />
      <inertia ixx="0.001" ixy="0.0" ixz="0.0"
        iyy="0.001" iyz="0.0"
        izz="0.001" />
    </inertial>

    <visual>
      <origin xyz=" 0 0 0 " rpy="0 0 0" />
      <geometry>
      <!--  <mesh filename="package://eddiebot_description/meshes/kinect.dae"/> -->
        <box size="0.08 0.28 0.08"/>
      </geometry>
      <material name="blue" />
    </visual>

    <collision>
      <origin xyz="0.0 0.0 0.0" rpy="0 0 0" />
      <geometry>
        <box size="0.08 0.28 0.08"/>
      </geometry>
    </collision>

  </link>

  <joint name="bars_1_joint" type="fixed">
    <origin xyz="0.10 0.18 0.0925" rpy="0 0 0" />
    <parent link="base_link" />
    <child link="bar_1_link" />
  </joint>

  <link name="bar_1_link">

    <inertial>
      <mass value="0.001" />
      <origin xyz="0 0 0" />
      <inertia ixx="0.0001" ixy="0.0" ixz="0.0"
          iyy="0.0001" iyz="0.0"
          izz="0.0001" />
    </inertial>

    <visual>
      <origin xyz=" 0 0 0 " rpy="0 0 0" />
      <geometry>
        <cylinder radius="0.005" length = "0.185"/>
      </geometry>
    </visual>

    <collision>
      <origin xyz="0.0 0.0 0.0" rpy="0 0 0" />
      <geometry>
        <cylinder radius="0.005" length = "0.185"/>
      </geometry>
    </collision>

  </link>

  <joint name="bars_2_joint" type="fixed">
    <origin xyz="0.10 -0.18 0.0925" rpy="0 0 0" />
    <parent link="base_link" />
    <child link="bar_2_link" />
  </joint>

  <link name="bar_2_link">

    <inertial>
      <mass value="0.001" />
      <origin xyz="0 0 0" />
      <inertia ixx="0.0001" ixy="0.0" ixz="0.0"
          iyy="0.0001" iyz="0.0"
          izz="0.0001" />
    </inertial>

    <visual>
      <origin xyz=" 0 0 0 " rpy="0 0 0" />
      <geometry>
        <cylinder radius="0.005" length = "0.185"/>
      </geometry>
    </visual>

    <collision>
      <origin xyz="0.0 0.0 0.0" rpy="0 0 0" />
      <geometry>
        <cylinder radius="0.005" length = "0.185"/>
      </geometry>
    </collision>

  </link>

  <joint name="bars_3_joint" type="fixed">
    <origin xyz="-0.10 0.18 0.0925" rpy="0 0 0" />
    <parent link="base_link" />
    <child link="bar_3_link" />
  </joint>

  <link name="bar_3_link">

    <inertial>
      <mass value="0.001" />
      <origin xyz="0 0 0" />
      <inertia ixx="0.0001" ixy="0.0" ixz="0.0"
          iyy="0.0001" iyz="0.0"
          izz="0.0001" />
    </inertial>

    <visual>
      <origin xyz=" 0 0 0 " rpy="0 0 0" />
      <geometry>
        <cylinder radius="0.005" length = "0.185"/>
      </geometry>
    </visual>

    <collision>
      <origin xyz="0.0 0.0 0.0" rpy="0 0 0" />
      <geometry>
        <cylinder radius="0.005" length = "0.185"/>
      </geometry>
    </collision>

  </link>

  <joint name="bars_4_joint" type="fixed">
    <origin xyz="-0.10 -0.18 0.0925" rpy="0 0 0" />
    <parent link="base_link" />
    <child link="bar_4_link" />
  </joint>

  <link name="bar_4_link">

    <inertial>
      <mass value="0.001" />
      <origin xyz="0 0 0" />
      <inertia ixx="0.0001" ixy="0.0" ixz="0.0"
          iyy="0.0001" iyz="0.0"
          izz="0.0001" />
    </inertial>

    <visual>
      <origin xyz=" 0 0 0 " rpy="0 0 0" />
      <geometry>
        <cylinder radius="0.005" length = "0.185"/>
      </geometry>
    </visual>

    <collision>
      <origin xyz="0.0 0.0 0.0" rpy="0 0 0" />
      <geometry>
        <cylinder radius="0.005" length = "0.185"/>
      </geometry>
    </collision>

  </link>

  <joint name="bars_5_joint" type="fixed">
    <origin xyz="0.065 0.18 0.1385" rpy="0 0 0" />
    <parent link="plate_0_link" />
    <child link="bar_5_link" />
  </joint>

  <link name="bar_5_link">

    <inertial>
      <mass value="0.001" />
      <origin xyz="0 0 0" />
      <inertia ixx="0.0001" ixy="0.0" ixz="0.0"
          iyy="0.0001" iyz="0.0"
          izz="0.0001" />
    </inertial>

    <visual>
      <origin xyz=" 0 0 0 " rpy="0 0 0" />
      <geometry>
        <cylinder radius="0.005" length = "0.275"/>
      </geometry>
    </visual>

    <collision>
      <origin xyz="0.0 0.0 0.0" rpy="0 0 0" />
      <geometry>
        <cylinder radius="0.005" length = "0.275"/>
      </geometry>
    </collision>

  </link>

  <joint name="bars_6_joint" type="fixed">
    <origin xyz="0.065 -0.18 0.1385" rpy="0 0 0" />
    <parent link="plate_0_link" />
    <child link="bar_6_link" />
  </joint>

  <link name="bar_6_link">

    <inertial>
      <mass value="0.001" />
      <origin xyz="0 0 0" />
      <inertia ixx="0.0001" ixy="0.0" ixz="0.0"
          iyy="0.0001" iyz="0.0"
          izz="0.0001" />
    </inertial>

    <visual>
      <origin xyz=" 0 0 0 " rpy="0 0 0" />
      <geometry>
        <cylinder radius="0.005" length = "0.275"/>
      </geometry>
    </visual>

    <collision>
      <origin xyz="0.0 0.0 0.0" rpy="0 0 0" />
      <geometry>
        <cylinder radius="0.005" length = "0.275"/>
      </geometry>
    </collision>

  </link>

  <joint name="bars_7_joint" type="fixed">
    <origin xyz="-0.065 0.18 0.1385" rpy="0 0 0" />
    <parent link="plate_0_link" />
    <child link="bar_7_link" />
  </joint>

  <link name="bar_7_link">

    <inertial>
      <mass value="0.001" />
      <origin xyz="0 0 0" />
      <inertia ixx="0.0001" ixy="0.0" ixz="0.0"
          iyy="0.0001" iyz="0.0"
          izz="0.0001" />
    </inertial>

    <visual>
      <origin xyz=" 0 0 0 " rpy="0 0 0" />
      <geometry>
        <cylinder radius="0.005" length = "0.275"/>
      </geometry>
    </visual>

    <collision>
      <origin xyz="0.0 0.0 0.0" rpy="0 0 0" />
      <geometry>
        <cylinder radius="0.005" length = "0.275"/>
      </geometry>
    </collision>

  </link>

  <joint name="bars_8_joint" type="fixed">
    <origin xyz="-0.065 -0.18 0.1385" rpy="0 0 0" />
    <parent link="plate_0_link" />
    <child link="bar_8_link" />
  </joint>

  <link name="bar_8_link">

    <inertial>
      <mass value="0.001" />
      <origin xyz="0 0 0" />
      <inertia ixx="0.0001" ixy="0.0" ixz="0.0"
          iyy="0.0001" iyz="0.0"
          izz="0.0001" />
    </inertial>

    <visual>
      <origin xyz=" 0 0 0 " rpy="0 0 0" />
      <geometry>
        <cylinder radius="0.005" length = "0.275"/>
      </geometry>
    </visual>

    <collision>
      <origin xyz="0.0 0.0 0.0" rpy="0 0 0" />
      <geometry>
        <cylinder radius="0.005" length = "0.275"/>
      </geometry>
    </collision>

  </link>

  <joint name="base_laptop_joint" type="fixed">
    <origin xyz="-0.173 0 0.015" rpy="0 0 0" />
    <parent link="plate_1_link" />
    <child link="base_laptop_link" />
  </joint>

  <link name="base_laptop_link">

    <inertial>
      <mass value="0.001" />
      <origin xyz="0 0 0" />
      <inertia ixx="0.0001" ixy="0.0" ixz="0.0"
          iyy="0.0001" iyz="0.0"
          izz="0.0001" />
    </inertial>

    <visual>
      <origin xyz=" 0 0 0 " rpy="0 0 0" />
      <geometry>
        <box size="0.266 0.37 0.02"/>
      </geometry>
      <material name="white" />
    </visual>

    <collision>
      <origin xyz="0.0 0.0 0.0" rpy="0 0 0" />
      <geometry>
        <box size="0.266 0.37 0.02"/>
      </geometry>
    </collision>

  </link>

  </xacro:macro>

</robot>
